Workbook

Sheet Ingot
A1: POE: Material Rarity Calc | G1: Table Overview
B2: Normal POE Weight | C2: POE Count | G2: Category | H2: Lightest Material | I2: Min Ingot | J2: Heaviest Material | K2: Max Ingot | L2: # Materials
A3: Cloth | B3: 0.25 – 0.52 | C3: =COUNTIFS(Table2[Home POE],"Material",Table2[Category],A3) -> 8 | G3: Cloth | H3: {=INDEX($H$12:$H$119,MATCH(1,($G$12:$G$119=G3)*($I$12:$I$119=I3),0))} -> Silk | I3: =ROUND(_xlfn.MINIFS($I$12:$I$119,$G$12:$G$119,G3,$I$12:$I$119,">0"),2) -> 0.25 | J3: {=INDEX($H$12:$H$119,MATCH(1,($G$12:$G$119=G3)*($I$12:$I$119=K3),0))} -> Wetsulf | K3: =ROUND(_xlfn.MAXIFS($I$12:$I$119,$G$12:$G$119,G3,$I$12:$I$119,">0"),2) -> 5.1 | L3: =COUNTIFS($G$12:$G$119,G3,$I$12:$I$119,">0") -> 12
A4: Leather | B4: 0.42 – 0.97 | C4: =COUNTIFS(Table2[Home POE],"Material",Table2[Category],A4) -> 3 | G4: Leather | H4: {=INDEX($H$12:$H$119,MATCH(1,($G$12:$G$119=G4)*(ROUND($I$12:$I$119,2)=I4),0))} -> Olyther | I4: =ROUND(_xlfn.MINIFS($I$12:$I$119,$G$12:$G$119,G4,$I$12:$I$119,">0"),2) -> 1.75 | J4: {=INDEX($H$12:$H$119,MATCH(1,($G$12:$G$119=G4)*(ROUND($I$12:$I$119,2)=K4),0))} -> Pelt | K4: =ROUND(_xlfn.MAXIFS($I$12:$I$119,$G$12:$G$119,G4,$I$12:$I$119,">0"),2) -> 5.83 | L4: =COUNTIFS($G$12:$G$119,G4,$I$12:$I$119,">0") -> 12
A5: Wood | B5: 0.79 – 1.82 | C5: =COUNTIFS(Table2[Home POE],"Material",Table2[Category],A5) -> 12 | G5: Wood | H5: {=INDEX($H$12:$H$119,MATCH(1,($G$12:$G$119=G5)*($I$12:$I$119=I5),0))} -> Pine | I5: =ROUND(_xlfn.MINIFS($I$12:$I$119,$G$12:$G$119,G5,$I$12:$I$119,">0"),2) -> 4.5 | J5: {=INDEX($H$12:$H$119,MATCH(1,($G$12:$G$119=G5)*($I$12:$I$119=K5),0))} -> Oak | K5: =ROUND(_xlfn.MAXIFS($I$12:$I$119,$G$12:$G$119,G5,$I$12:$I$119,">0"),2) -> 13 | L5: =COUNTIFS($G$12:$G$119,G5,$I$12:$I$119,">0") -> 11
A6: Osso | B6: 1.49 – 3.42 | C6: =COUNTIFS(Table2[Home POE],"Material",Table2[Category],A6) -> 5 | G6: Osso | H6: {=INDEX($H$12:$H$119,MATCH(1,($G$12:$G$119=G6)*($I$12:$I$119=I6),0))} -> Ohmu | I6: =ROUND(_xlfn.MINIFS($I$12:$I$119,$G$12:$G$119,G6,$I$12:$I$119,">0"),2) -> 4 | J6: {=INDEX($H$12:$H$119,MATCH(1,($G$12:$G$119=G6)*($I$12:$I$119=K6),0))} -> Bonemold | K6: =ROUND(_xlfn.MAXIFS($I$12:$I$119,$G$12:$G$119,G6,$I$12:$I$119,">0"),2) -> 14 | L6: =COUNTIFS($G$12:$G$119,G6,$I$12:$I$119,">0") -> 6
A7: Glass | B7: 2.79 – 6.40 | C7: =COUNTIFS(Table2[Home POE],"Material",Table2[Category],A7) -> 4 | G7: Glass | H7: {=INDEX($H$12:$H$119,MATCH(1,($G$12:$G$119=G7)*($I$12:$I$119=I7),0))} -> Lass | I7: =ROUND(_xlfn.MINIFS($I$12:$I$119,$G$12:$G$119,G7,$I$12:$I$119,">0"),2) -> 6 | J7: {=INDEX($H$12:$H$119,MATCH(1,($G$12:$G$119=G7)*($I$12:$I$119=K7),0))} -> Ebony | K7: =ROUND(_xlfn.MAXIFS($I$12:$I$119,$G$12:$G$119,G7,$I$12:$I$119,">0"),2) -> 17.5 | L7: =COUNTIFS($G$12:$G$119,G7,$I$12:$I$119,">0") -> 11
A8: Stone | B8: 5.22 – 11.98 | C8: =COUNTIFS(Table2[Home POE],"Material",Table2[Category],A8) -> 9 | G8: Stone | H8: {=INDEX($H$12:$H$119,MATCH(1,($G$12:$G$119=G8)*($I$12:$I$119=I8),0))} -> Trueice | I8: =ROUND(_xlfn.MINIFS($I$12:$I$119,$G$12:$G$119,G8,$I$12:$I$119,">0"),2) -> 8 | J8: {=INDEX($H$12:$H$119,MATCH(1,($G$12:$G$119=G8)*($I$12:$I$119=K8),0))} -> Elysian | K8: =ROUND(_xlfn.MAXIFS($I$12:$I$119,$G$12:$G$119,G8,$I$12:$I$119,">0"),2) -> 19.5 | L8: =COUNTIFS($G$12:$G$119,G8,$I$12:$I$119,">0") -> 8
A9: Metal | B9: 9.78 – 20.00 | C9: =COUNTIFS(Table2[Home POE],"Material",Table2[Category],A9) -> 12 | G9: Metal | H9: {=INDEX($H$12:$H$119,MATCH(1,($G$12:$G$119=G9)*($I$12:$I$119=I9),0))} -> Tin | I9: =ROUND(_xlfn.MINIFS($I$12:$I$119,$G$12:$G$119,G9,$I$12:$I$119,">0"),2) -> 7 | J9: {=INDEX($H$12:$H$119,MATCH(1,($G$12:$G$119=G9)*($I$12:$I$119=K9),0))} -> Adamantine | K9: =ROUND(_xlfn.MAXIFS($I$12:$I$119,$G$12:$G$119,G9,$I$12:$I$119,">0"),2) -> 20 | L9: =COUNTIFS($G$12:$G$119,G9,$I$12:$I$119,">0") -> 13
A10: POE: Underdark Rarity Calc | G10: Table
B11: Normal POE Weight | G11: Category | H11: Craft | I11: Ingot | J11: Heaviest Item | K11: Lightest Item | L11: Heaviest Name | M11: Lightest Name | N11: Weapon LBs | O11: Armor LBs | P11: LBs Avg | Q11: Home POE | R11: Home Plane Rarity
A12: Cloth | B12: 0.25 – 0.52 | C12: =COUNTIFS(Table2[Home POE],"Underdark",Table2[Category],A12) -> 0 | G12: Leather | H12: Abyski | I12: 4 | J12: =_xlfn.MAXIFS(Import!$G$2:$G$12853,Import!$B$2:$B$12853,$H12) -> 22.67 | K12: =_xlfn.MINIFS(Import!$G$2:$G$12853,Import!$B$2:$B$12853,$H12) -> 0.04 | L12: {=IFERROR(_xlfn.TEXTAFTER(INDEX(Import!$D$2:$D$12853,MATCH(1,(Import!$B$2:$B$12853=$H12)*(Import!$G$2:$G$12853=$J12),0))," "),"")} -> Hunting Trap (Large) | M12: {=IFERROR(_xlfn.TEXTAFTER(INDEX(Import!$D$2:$D$12853,MATCH(1,(Import!$B$2:$B$12853=$H12)*(Import!$G$2:$G$12853=$K12),0))," "),"")} -> Bolt | N12: =SUMIFS(Import!$G$2:$G$12853,Import!$B$2:$B$12853,$H12,Import!$C$2:$C$12853,"Weapon") -> 356.9 | O12: =SUMIFS(Import!$G$2:$G$12853,Import!$B$2:$B$12853,$H12,Import!$C$2:$C$12853,"Armor") -> 329.42 | P12: =AVERAGE(N12:O12) -> 343.16 | Q12: =_xlfn.LET(_xlpm.v,_xlfn.XLOOKUP(Table2[[#This Row],[Craft]],Table4[Material],Table4[Home POE],""),IF(_xlpm.v="","",_xlpm.v)) | R12: =_xlfn.LET(_xlpm.v,_xlfn.XLOOKUP(Table2[[#This Row],[Craft]],Table4[Material],Table4[Home Rarity],""),IF(_xlpm.v="","",_xlpm.v))
A13: Leather | B13: 0.42 – 0.97 | C13: =COUNTIFS(Table2[Home POE],"Underdark",Table2[Category],A13) -> 0 | G13: Metal | H13: Adamantine | I13: 20 | J13: =_xlfn.MAXIFS(Import!$G$2:$G$12853,Import!$B$2:$B$12853,$H13) -> 49.75 | K13: =_xlfn.MINIFS(Import!$G$2:$G$12853,Import!$B$2:$B$12853,$H13) -> 0.04 | L13: {=IFERROR(_xlfn.TEXTAFTER(INDEX(Import!$D$2:$D$12853,MATCH(1,(Import!$B$2:$B$12853=$H13)*(Import!$G$2:$G$12853=$J13),0))," "),"")} -> Tower Shield | M13: {=IFERROR(_xlfn.TEXTAFTER(INDEX(Import!$D$2:$D$12853,MATCH(1,(Import!$B$2:$B$12853=$H13)*(Import!$G$2:$G$12853=$K13),0))," "),"")} -> Bolt | N13: =SUMIFS(Import!$G$2:$G$12853,Import!$B$2:$B$12853,$H13,Import!$C$2:$C$12853,"Weapon") -> 356.9 | O13: =SUMIFS(Import!$G$2:$G$12853,Import!$B$2:$B$12853,$H13,Import!$C$2:$C$12853,"Armor") -> 506.71 | P13: =AVERAGE(N13:O13) -> 431.805 | Q13: =_xlfn.LET(_xlpm.v,_xlfn.XLOOKUP(Table2[[#This Row],[Craft]],Table4[Material],Table4[Home POE],""),IF(_xlpm.v="","",_xlpm.v)) -> Material | R13: =_xlfn.LET(_xlpm.v,_xlfn.XLOOKUP(Table2[[#This Row],[Craft]],Table4[Material],Table4[Home Rarity],""),IF(_xlpm.v="","",_xlpm.v)) -> 4
A14: Wood | B14: 0.79 – 1.82 | C14: =COUNTIFS(Table2[Home POE],"Underdark",Table2[Category],A14) -> 0 | G14: Glass | H14: Amber | I14: 7 | J14: =_xlfn.MAXIFS(Import!$G$2:$G$12853,Import!$B$2:$B$12853,$H14) -> 31 | K14: =_xlfn.MINIFS(Import!$G$2:$G$12853,Import!$B$2:$B$12853,$H14) -> 0.04 | L14: {=IFERROR(_xlfn.TEXTAFTER(INDEX(Import!$D$2:$D$12853,MATCH(1,(Import!$B$2:$B$12853=$H14)*(Import!$G$2:$G$12853=$J14),0))," "),"")} -> Lamellar Cuirass | M14: {=IFERROR(_xlfn.TEXTAFTER(INDEX(Import!$D$2:$D$12853,MATCH(1,(Import!$B$2:$B$12853=$H14)*(Import!$G$2:$G$12853=$K14),0))," "),"")} -> Bolt | N14: =SUMIFS(Import!$G$2:$G$12853,Import!$B$2:$B$12853,$H14,Import!$C$2:$C$12853,"Weapon") -> 356.9 | O14: =SUMIFS(Import!$G$2:$G$12853,Import!$B$2:$B$12853,$H14,Import!$C$2:$C$12853,"Armor") -> 415 | P14: =AVERAGE(N14:O14) -> 385.95 | Q14: =_xlfn.LET(_xlpm.v,_xlfn.XLOOKUP(Table2[[#This Row],[Craft]],Table4[Material],Table4[Home POE],""),IF(_xlpm.v="","",_xlpm.v)) -> Material | R14: =_xlfn.LET(_xlpm.v,_xlfn.XLOOKUP(Table2[[#This Row],[Craft]],Table4[Material],Table4[Home Rarity],""),IF(_xlpm.v="","",_xlpm.v)) -> 3
A15: Osso | B15: 1.49 – 3.42 | C15: =COUNTIFS(Table2[Home POE],"Underdark",Table2[Category],A15) -> 0 | G15: Metal | H15: Arandur | J15: =_xlfn.MAXIFS(Import!$G$2:$G$12853,Import!$B$2:$B$12853,$H15) -> 38 | K15: =_xlfn.MINIFS(Import!$G$2:$G$12853,Import!$B$2:$B$12853,$H15) -> 0.04 | L15: {=IFERROR(_xlfn.TEXTAFTER(INDEX(Import!$D$2:$D$12853,MATCH(1,(Import!$B$2:$B$12853=$H15)*(Import!$G$2:$G$12853=$J15),0))," "),"")} -> Lamellar Cuirass | M15: {=IFERROR(_xlfn.TEXTAFTER(INDEX(Import!$D$2:$D$12853,MATCH(1,(Import!$B$2:$B$12853=$H15)*(Import!$G$2:$G$12853=$K15),0))," "),"")} -> Bolt | N15: =SUMIFS(Import!$G$2:$G$12853,Import!$B$2:$B$12853,$H15,Import!$C$2:$C$12853,"Weapon") -> 356.9 | O15: =SUMIFS(Import!$G$2:$G$12853,Import!$B$2:$B$12853,$H15,Import!$C$2:$C$12853,"Armor") -> 483.3 | P15: =AVERAGE(N15:O15) -> 420.1 | Q15: =_xlfn.LET(_xlpm.v,_xlfn.XLOOKUP(Table2[[#This Row],[Craft]],Table4[Material],Table4[Home POE],""),IF(_xlpm.v="","",_xlpm.v)) -> Feywild | R15: =_xlfn.LET(_xlpm.v,_xlfn.XLOOKUP(Table2[[#This Row],[Craft]],Table4[Material],Table4[Home Rarity],""),IF(_xlpm.v="","",_xlpm.v))
A16: Glass | B16: 2.79 – 6.40 | C16: =COUNTIFS(Table2[Home POE],"Underdark",Table2[Category],A16) -> 0 | G16: Wood | H16: Ash | I16: 11.5 | J16: =_xlfn.MAXIFS(Import!$G$2:$G$12853,Import!$B$2:$B$12853,$H16) -> 27.55 | K16: =_xlfn.MINIFS(Import!$G$2:$G$12853,Import!$B$2:$B$12853,$H16) -> 0.04 | L16: {=IFERROR(_xlfn.TEXTAFTER(INDEX(Import!$D$2:$D$12853,MATCH(1,(Import!$B$2:$B$12853=$H16)*(Import!$G$2:$G$12853=$J16),0))," "),"")} -> Lamellar Cuirass | M16: {=IFERROR(_xlfn.TEXTAFTER(INDEX(Import!$D$2:$D$12853,MATCH(1,(Import!$B$2:$B$12853=$H16)*(Import!$G$2:$G$12853=$K16),0))," "),"")} -> Bolt | N16: =SUMIFS(Import!$G$2:$G$12853,Import!$B$2:$B$12853,$H16,Import!$C$2:$C$12853,"Weapon") -> 356.9 | O16: =SUMIFS(Import!$G$2:$G$12853,Import!$B$2:$B$12853,$H16,Import!$C$2:$C$12853,"Armor") -> 388.82 | P16: =AVERAGE(N16:O16) -> 372.86 | Q16: =_xlfn.LET(_xlpm.v,_xlfn.XLOOKUP(Table2[[#This Row],[Craft]],Table4[Material],Table4[Home POE],""),IF(_xlpm.v="","",_xlpm.v)) -> Material | R16: =_xlfn.LET(_xlpm.v,_xlfn.XLOOKUP(Table2[[#This Row],[Craft]],Table4[Material],Table4[Home Rarity],""),IF(_xlpm.v="","",_xlpm.v)) -> 1
A17: Stone | B17: 5.22 – 11.98 | C17: =COUNTIFS(Table2[Home POE],"Underdark",Table2[Category],A17) -> 0 | G17: Metal | H17: Aurorum | J17: =_xlfn.MAXIFS(Import!$G$2:$G$12853,Import!$B$2:$B$12853,$H17) -> 38 | K17: =_xlfn.MINIFS(Import!$G$2:$G$12853,Import!$B$2:$B$12853,$H17) -> 0.04 | L17: {=IFERROR(_xlfn.TEXTAFTER(INDEX(Import!$D$2:$D$12853,MATCH(1,(Import!$B$2:$B$12853=$H17)*(Import!$G$2:$G$12853=$J17),0))," "),"")} -> Lamellar Cuirass | M17: {=IFERROR(_xlfn.TEXTAFTER(INDEX(Import!$D$2:$D$12853,MATCH(1,(Import!$B$2:$B$12853=$H17)*(Import!$G$2:$G$12853=$K17),0))," "),"")} -> Bolt | N17: =SUMIFS(Import!$G$2:$G$12853,Import!$B$2:$B$12853,$H17,Import!$C$2:$C$12853,"Weapon") -> 356.9 | O17: =SUMIFS(Import!$G$2:$G$12853,Import!$B$2:$B$12853,$H17,Import!$C$2:$C$12853,"Armor") -> 483.3 | P17: =AVERAGE(N17:O17) -> 420.1 | Q17: =_xlfn.LET(_xlpm.v,_xlfn.XLOOKUP(Table2[[#This Row],[Craft]],Table4[Material],Table4[Home POE],""),IF(_xlpm.v="","",_xlpm.v)) -> Upper | R17: =_xlfn.LET(_xlpm.v,_xlfn.XLOOKUP(Table2[[#This Row],[Craft]],Table4[Material],Table4[Home Rarity],""),IF(_xlpm.v="","",_xlpm.v)) -> 5
A18: Metal | B18: 9.78 – 20.00 | C18: =COUNTIFS(Table2[Home POE],"Underdark",Table2[Category],A18) -> 0 | G18: Metal | H18: Baatorium | I18: 18 | J18: =_xlfn.MAXIFS(Import!$G$2:$G$12853,Import!$B$2:$B$12853,$H18) -> 43.75 | K18: =_xlfn.MINIFS(Import!$G$2:$G$12853,Import!$B$2:$B$12853,$H18) -> 0.04 | L18: {=IFERROR(_xlfn.TEXTAFTER(INDEX(Import!$D$2:$D$12853,MATCH(1,(Import!$B$2:$B$12853=$H18)*(Import!$G$2:$G$12853=$J18),0))," "),"")} -> Tower Shield | M18: {=IFERROR(_xlfn.TEXTAFTER(INDEX(Import!$D$2:$D$12853,MATCH(1,(Import!$B$2:$B$12853=$H18)*(Import!$G$2:$G$12853=$K18),0))," "),"")} -> Bolt | N18: =SUMIFS(Import!$G$2:$G$12853,Import!$B$2:$B$12853,$H18,Import!$C$2:$C$12853,"Weapon") -> 356.9 | O18: =SUMIFS(Import!$G$2:$G$12853,Import!$B$2:$B$12853,$H18,Import!$C$2:$C$12853,"Armor") -> 500.29 | P18: =AVERAGE(N18:O18) -> 428.595 | Q18: =_xlfn.LET(_xlpm.v,_xlfn.XLOOKUP(Table2[[#This Row],[Craft]],Table4[Material],Table4[Home POE],""),IF(_xlpm.v="","",_xlpm.v)) -> Lower | R18: =_xlfn.LET(_xlpm.v,_xlfn.XLOOKUP(Table2[[#This Row],[Craft]],Table4[Material],Table4[Home Rarity],""),IF(_xlpm.v="","",_xlpm.v)) -> 3
A19: POE: Upper Rarity Calc | G19: Glass | H19: Beskar | I19: 12 | J19: =_xlfn.MAXIFS(Import!$G$2:$G$12853,Import!$B$2:$B$12853,$H19) -> 32.5 | K19: =_xlfn.MINIFS(Import!$G$2:$G$12853,Import!$B$2:$B$12853,$H19) -> 0.04 | L19: {=IFERROR(_xlfn.TEXTAFTER(INDEX(Import!$D$2:$D$12853,MATCH(1,(Import!$B$2:$B$12853=$H19)*(Import!$G$2:$G$12853=$J19),0))," "),"")} -> Lamellar Cuirass | M19: {=IFERROR(_xlfn.TEXTAFTER(INDEX(Import!$D$2:$D$12853,MATCH(1,(Import!$B$2:$B$12853=$H19)*(Import!$G$2:$G$12853=$K19),0))," "),"")} -> Bolt | N19: =SUMIFS(Import!$G$2:$G$12853,Import!$B$2:$B$12853,$H19,Import!$C$2:$C$12853,"Weapon") -> 356.9 | O19: =SUMIFS(Import!$G$2:$G$12853,Import!$B$2:$B$12853,$H19,Import!$C$2:$C$12853,"Armor") -> 430.2 | P19: =AVERAGE(N19:O19) -> 393.55 | Q19: =_xlfn.LET(_xlpm.v,_xlfn.XLOOKUP(Table2[[#This Row],[Craft]],Table4[Material],Table4[Home POE],""),IF(_xlpm.v="","",_xlpm.v)) -> Material (other setting) | R19: =_xlfn.LET(_xlpm.v,_xlfn.XLOOKUP(Table2[[#This Row],[Craft]],Table4[Material],Table4[Home Rarity],""),IF(_xlpm.v="","",_xlpm.v)) -> 4
B20: Normal POE Weight | G20: Wood | H20: Birch | I20: 8 | J20: =_xlfn.MAXIFS(Import!$G$2:$G$12853,Import!$B$2:$B$12853,$H20) -> 26.53 | K20: =_xlfn.MINIFS(Import!$G$2:$G$12853,Import!$B$2:$B$12853,$H20) -> 0.04 | L20: {=IFERROR(_xlfn.TEXTAFTER(INDEX(Import!$D$2:$D$12853,MATCH(1,(Import!$B$2:$B$12853=$H20)*(Import!$G$2:$G$12853=$J20),0))," "),"")} -> Lamellar Cuirass | M20: {=IFERROR(_xlfn.TEXTAFTER(INDEX(Import!$D$2:$D$12853,MATCH(1,(Import!$B$2:$B$12853=$H20)*(Import!$G$2:$G$12853=$K20),0))," "),"")} -> Bolt | N20: =SUMIFS(Import!$G$2:$G$12853,Import!$B$2:$B$12853,$H20,Import!$C$2:$C$12853,"Weapon") -> 356.9 | O20: =SUMIFS(Import!$G$2:$G$12853,Import!$B$2:$B$12853,$H20,Import!$C$2:$C$12853,"Armor") -> 379.86 | P20: =AVERAGE(N20:O20) -> 368.38 | Q20: =_xlfn.LET(_xlpm.v,_xlfn.XLOOKUP(Table2[[#This Row],[Craft]],Table4[Material],Table4[Home POE],""),IF(_xlpm.v="","",_xlpm.v)) -> Material | R20: =_xlfn.LET(_xlpm.v,_xlfn.XLOOKUP(Table2[[#This Row],[Craft]],Table4[Material],Table4[Home Rarity],""),IF(_xlpm.v="","",_xlpm.v)) -> 1
A21: Cloth | B21: 0.25 – 0.52 | C21: =COUNTIFS(Table2[Home POE],"Upper",Table2[Category],A21) -> 0 | G21: Wood | H21: Bloodbark | J21: =_xlfn.MAXIFS(Import!$G$2:$G$12853,Import!$B$2:$B$12853,$H21) -> 26.8 | K21: =_xlfn.MINIFS(Import!$G$2:$G$12853,Import!$B$2:$B$12853,$H21) -> 0.04 | L21: {=IFERROR(_xlfn.TEXTAFTER(INDEX(Import!$D$2:$D$12853,MATCH(1,(Import!$B$2:$B$12853=$H21)*(Import!$G$2:$G$12853=$J21),0))," "),"")} -> Lamellar Cuirass | M21: {=IFERROR(_xlfn.TEXTAFTER(INDEX(Import!$D$2:$D$12853,MATCH(1,(Import!$B$2:$B$12853=$H21)*(Import!$G$2:$G$12853=$K21),0))," "),"")} -> Bolt | N21: =SUMIFS(Import!$G$2:$G$12853,Import!$B$2:$B$12853,$H21,Import!$C$2:$C$12853,"Weapon") -> 356.9 | O21: =SUMIFS(Import!$G$2:$G$12853,Import!$B$2:$B$12853,$H21,Import!$C$2:$C$12853,"Armor") -> 382.22 | P21: =AVERAGE(N21:O21) -> 369.56 | Q21: =_xlfn.LET(_xlpm.v,_xlfn.XLOOKUP(Table2[[#This Row],[Craft]],Table4[Material],Table4[Home POE],""),IF(_xlpm.v="","",_xlpm.v)) | R21: =_xlfn.LET(_xlpm.v,_xlfn.XLOOKUP(Table2[[#This Row],[Craft]],Table4[Material],Table4[Home Rarity],""),IF(_xlpm.v="","",_xlpm.v))
A22: Leather | B22: 0.42 – 0.97 | C22: =COUNTIFS(Table2[Home POE],"Upper",Table2[Category],A22) -> 0 | G22: Wood | H22: Bludbud | J22: =_xlfn.MAXIFS(Import!$G$2:$G$12853,Import!$B$2:$B$12853,$H22) -> 26.8 | K22: =_xlfn.MINIFS(Import!$G$2:$G$12853,Import!$B$2:$B$12853,$H22) -> 0.04 | L22: {=IFERROR(_xlfn.TEXTAFTER(INDEX(Import!$D$2:$D$12853,MATCH(1,(Import!$B$2:$B$12853=$H22)*(Import!$G$2:$G$12853=$J22),0))," "),"")} -> Lamellar Cuirass | M22: {=IFERROR(_xlfn.TEXTAFTER(INDEX(Import!$D$2:$D$12853,MATCH(1,(Import!$B$2:$B$12853=$H22)*(Import!$G$2:$G$12853=$K22),0))," "),"")} -> Bolt | N22: =SUMIFS(Import!$G$2:$G$12853,Import!$B$2:$B$12853,$H22,Import!$C$2:$C$12853,"Weapon") -> 356.9 | O22: =SUMIFS(Import!$G$2:$G$12853,Import!$B$2:$B$12853,$H22,Import!$C$2:$C$12853,"Armor") -> 382.22 | P22: =AVERAGE(N22:O22) -> 369.56 | Q22: =_xlfn.LET(_xlpm.v,_xlfn.XLOOKUP(Table2[[#This Row],[Craft]],Table4[Material],Table4[Home POE],""),IF(_xlpm.v="","",_xlpm.v)) | R22: =_xlfn.LET(_xlpm.v,_xlfn.XLOOKUP(Table2[[#This Row],[Craft]],Table4[Material],Table4[Home Rarity],""),IF(_xlpm.v="","",_xlpm.v))
A23: Wood | B23: 0.79 – 1.82 | C23: =COUNTIFS(Table2[Home POE],"Upper",Table2[Category],A23) -> 0 | G23: Stone | H23: Blueice | J23: =_xlfn.MAXIFS(Import!$G$2:$G$12853,Import!$B$2:$B$12853,$H23) -> 48.5 | K23: =_xlfn.MINIFS(Import!$G$2:$G$12853,Import!$B$2:$B$12853,$H23) -> 0.04 | L23: {=IFERROR(_xlfn.TEXTAFTER(INDEX(Import!$D$2:$D$12853,MATCH(1,(Import!$B$2:$B$12853=$H23)*(Import!$G$2:$G$12853=$J23),0))," "),"")} -> Lamellar Cuirass | M23: {=IFERROR(_xlfn.TEXTAFTER(INDEX(Import!$D$2:$D$12853,MATCH(1,(Import!$B$2:$B$12853=$H23)*(Import!$G$2:$G$12853=$K23),0))," "),"")} -> Bolt | N23: =SUMIFS(Import!$G$2:$G$12853,Import!$B$2:$B$12853,$H23,Import!$C$2:$C$12853,"Weapon") -> 356.9 | O23: =SUMIFS(Import!$G$2:$G$12853,Import!$B$2:$B$12853,$H23,Import!$C$2:$C$12853,"Armor") -> 624.74 | P23: =AVERAGE(N23:O23) -> 490.82 | Q23: =_xlfn.LET(_xlpm.v,_xlfn.XLOOKUP(Table2[[#This Row],[Craft]],Table4[Material],Table4[Home POE],""),IF(_xlpm.v="","",_xlpm.v)) -> Lower | R23: =_xlfn.LET(_xlpm.v,_xlfn.XLOOKUP(Table2[[#This Row],[Craft]],Table4[Material],Table4[Home Rarity],""),IF(_xlpm.v="","",_xlpm.v)) -> 3
A24: Osso | B24: 1.49 – 3.42 | C24: =COUNTIFS(Table2[Home POE],"Upper",Table2[Category],A24) -> 0 | G24: Wood | H24: Bluleaf | I24: 9 | J24: =_xlfn.MAXIFS(Import!$G$2:$G$12853,Import!$B$2:$B$12853,$H24) -> 26.8 | K24: =_xlfn.MINIFS(Import!$G$2:$G$12853,Import!$B$2:$B$12853,$H24) -> 0.04 | L24: {=IFERROR(_xlfn.TEXTAFTER(INDEX(Import!$D$2:$D$12853,MATCH(1,(Import!$B$2:$B$12853=$H24)*(Import!$G$2:$G$12853=$J24),0))," "),"")} -> Lamellar Cuirass | M24: {=IFERROR(_xlfn.TEXTAFTER(INDEX(Import!$D$2:$D$12853,MATCH(1,(Import!$B$2:$B$12853=$H24)*(Import!$G$2:$G$12853=$K24),0))," "),"")} -> Bolt | N24: =SUMIFS(Import!$G$2:$G$12853,Import!$B$2:$B$12853,$H24,Import!$C$2:$C$12853,"Weapon") -> 356.9 | O24: =SUMIFS(Import!$G$2:$G$12853,Import!$B$2:$B$12853,$H24,Import!$C$2:$C$12853,"Armor") -> 382.22 | P24: =AVERAGE(N24:O24) -> 369.56 | Q24: =_xlfn.LET(_xlpm.v,_xlfn.XLOOKUP(Table2[[#This Row],[Craft]],Table4[Material],Table4[Home POE],""),IF(_xlpm.v="","",_xlpm.v)) | R24: =_xlfn.LET(_xlpm.v,_xlfn.XLOOKUP(Table2[[#This Row],[Craft]],Table4[Material],Table4[Home Rarity],""),IF(_xlpm.v="","",_xlpm.v))
A25: Glass | B25: 2.79 – 6.40 | C25: =COUNTIFS(Table2[Home POE],"Upper",Table2[Category],A25) -> 0 | G25: Leather | H25: Boiplate | I25: 3 | J25: =_xlfn.MAXIFS(Import!$G$2:$G$12853,Import!$B$2:$B$12853,$H25) -> 22.67 | K25: =_xlfn.MINIFS(Import!$G$2:$G$12853,Import!$B$2:$B$12853,$H25) -> 0.04 | L25: {=IFERROR(_xlfn.TEXTAFTER(INDEX(Import!$D$2:$D$12853,MATCH(1,(Import!$B$2:$B$12853=$H25)*(Import!$G$2:$G$12853=$J25),0))," "),"")} -> Hunting Trap (Large) | M25: {=IFERROR(_xlfn.TEXTAFTER(INDEX(Import!$D$2:$D$12853,MATCH(1,(Import!$B$2:$B$12853=$H25)*(Import!$G$2:$G$12853=$K25),0))," "),"")} -> Bolt | N25: =SUMIFS(Import!$G$2:$G$12853,Import!$B$2:$B$12853,$H25,Import!$C$2:$C$12853,"Weapon") -> 356.9 | O25: =SUMIFS(Import!$G$2:$G$12853,Import!$B$2:$B$12853,$H25,Import!$C$2:$C$12853,"Armor") -> 328.3 | P25: =AVERAGE(N25:O25) -> 342.6 | Q25: =_xlfn.LET(_xlpm.v,_xlfn.XLOOKUP(Table2[[#This Row],[Craft]],Table4[Material],Table4[Home POE],""),IF(_xlpm.v="","",_xlpm.v)) | R25: =_xlfn.LET(_xlpm.v,_xlfn.XLOOKUP(Table2[[#This Row],[Craft]],Table4[Material],Table4[Home Rarity],""),IF(_xlpm.v="","",_xlpm.v))
A26: Stone | B26: 5.22 – 11.98 | C26: =COUNTIFS(Table2[Home POE],"Upper",Table2[Category],A26) -> 1 | G26: Osso | H26: Bone | I26: 5.5 | J26: =_xlfn.MAXIFS(Import!$G$2:$G$12853,Import!$B$2:$B$12853,$H26) -> 22.67 | K26: =_xlfn.MINIFS(Import!$G$2:$G$12853,Import!$B$2:$B$12853,$H26) -> 0.04 | L26: {=IFERROR(_xlfn.TEXTAFTER(INDEX(Import!$D$2:$D$12853,MATCH(1,(Import!$B$2:$B$12853=$H26)*(Import!$G$2:$G$12853=$J26),0))," "),"")} -> Hunting Trap (Large) | M26: {=IFERROR(_xlfn.TEXTAFTER(INDEX(Import!$D$2:$D$12853,MATCH(1,(Import!$B$2:$B$12853=$H26)*(Import!$G$2:$G$12853=$K26),0))," "),"")} -> Bolt | N26: =SUMIFS(Import!$G$2:$G$12853,Import!$B$2:$B$12853,$H26,Import!$C$2:$C$12853,"Weapon") -> 356.9 | O26: =SUMIFS(Import!$G$2:$G$12853,Import!$B$2:$B$12853,$H26,Import!$C$2:$C$12853,"Armor") -> 348.8 | P26: =AVERAGE(N26:O26) -> 352.85 | Q26: =_xlfn.LET(_xlpm.v,_xlfn.XLOOKUP(Table2[[#This Row],[Craft]],Table4[Material],Table4[Home POE],""),IF(_xlpm.v="","",_xlpm.v)) -> Material | R26: =_xlfn.LET(_xlpm.v,_xlfn.XLOOKUP(Table2[[#This Row],[Craft]],Table4[Material],Table4[Home Rarity],""),IF(_xlpm.v="","",_xlpm.v)) -> 1
A27: Metal | B27: 9.78 – 20.00 | C27: =COUNTIFS(Table2[Home POE],"Upper",Table2[Category],A27) -> 1 | G27: Osso | H27: Bonemold | I27: 14 | J27: =_xlfn.MAXIFS(Import!$G$2:$G$12853,Import!$B$2:$B$12853,$H27) -> 31.75 | K27: =_xlfn.MINIFS(Import!$G$2:$G$12853,Import!$B$2:$B$12853,$H27) -> 0.04 | L27: {=IFERROR(_xlfn.TEXTAFTER(INDEX(Import!$D$2:$D$12853,MATCH(1,(Import!$B$2:$B$12853=$H27)*(Import!$G$2:$G$12853=$J27),0))," "),"")} -> Tower Shield | M27: {=IFERROR(_xlfn.TEXTAFTER(INDEX(Import!$D$2:$D$12853,MATCH(1,(Import!$B$2:$B$12853=$H27)*(Import!$G$2:$G$12853=$K27),0))," "),"")} -> Bolt | N27: =SUMIFS(Import!$G$2:$G$12853,Import!$B$2:$B$12853,$H27,Import!$C$2:$C$12853,"Weapon") -> 356.9 | O27: =SUMIFS(Import!$G$2:$G$12853,Import!$B$2:$B$12853,$H27,Import!$C$2:$C$12853,"Armor") -> 360 | P27: =AVERAGE(N27:O27) -> 358.45 | Q27: =_xlfn.LET(_xlpm.v,_xlfn.XLOOKUP(Table2[[#This Row],[Craft]],Table4[Material],Table4[Home POE],""),IF(_xlpm.v="","",_xlpm.v)) -> Material | R27: =_xlfn.LET(_xlpm.v,_xlfn.XLOOKUP(Table2[[#This Row],[Craft]],Table4[Material],Table4[Home Rarity],""),IF(_xlpm.v="","",_xlpm.v)) -> 2
A28: POE: Lower Rarity Calc | G28: Wood | H28: Bronwood | I28: 12.5 | J28: =_xlfn.MAXIFS(Import!$G$2:$G$12853,Import!$B$2:$B$12853,$H28) -> 27.85 | K28: =_xlfn.MINIFS(Import!$G$2:$G$12853,Import!$B$2:$B$12853,$H28) -> 0.04 | L28: {=IFERROR(_xlfn.TEXTAFTER(INDEX(Import!$D$2:$D$12853,MATCH(1,(Import!$B$2:$B$12853=$H28)*(Import!$G$2:$G$12853=$J28),0))," "),"")} -> Lamellar Cuirass | M28: {=IFERROR(_xlfn.TEXTAFTER(INDEX(Import!$D$2:$D$12853,MATCH(1,(Import!$B$2:$B$12853=$H28)*(Import!$G$2:$G$12853=$K28),0))," "),"")} -> Bolt | N28: =SUMIFS(Import!$G$2:$G$12853,Import!$B$2:$B$12853,$H28,Import!$C$2:$C$12853,"Weapon") -> 356.9 | O28: =SUMIFS(Import!$G$2:$G$12853,Import!$B$2:$B$12853,$H28,Import!$C$2:$C$12853,"Armor") -> 391.48 | P28: =AVERAGE(N28:O28) -> 374.19 | Q28: =_xlfn.LET(_xlpm.v,_xlfn.XLOOKUP(Table2[[#This Row],[Craft]],Table4[Material],Table4[Home POE],""),IF(_xlpm.v="","",_xlpm.v)) | R28: =_xlfn.LET(_xlpm.v,_xlfn.XLOOKUP(Table2[[#This Row],[Craft]],Table4[Material],Table4[Home Rarity],""),IF(_xlpm.v="","",_xlpm.v))
B29: Normal POE Weight | G29: Metal | H29: Bronze | I29: 8.5 | J29: =_xlfn.MAXIFS(Import!$G$2:$G$12853,Import!$B$2:$B$12853,$H29) -> 36.93 | K29: =_xlfn.MINIFS(Import!$G$2:$G$12853,Import!$B$2:$B$12853,$H29) -> 0.04 | L29: {=IFERROR(_xlfn.TEXTAFTER(INDEX(Import!$D$2:$D$12853,MATCH(1,(Import!$B$2:$B$12853=$H29)*(Import!$G$2:$G$12853=$J29),0))," "),"")} -> Lamellar Cuirass | M29: {=IFERROR(_xlfn.TEXTAFTER(INDEX(Import!$D$2:$D$12853,MATCH(1,(Import!$B$2:$B$12853=$H29)*(Import!$G$2:$G$12853=$K29),0))," "),"")} -> Bolt | N29: =SUMIFS(Import!$G$2:$G$12853,Import!$B$2:$B$12853,$H29,Import!$C$2:$C$12853,"Weapon") -> 356.9 | O29: =SUMIFS(Import!$G$2:$G$12853,Import!$B$2:$B$12853,$H29,Import!$C$2:$C$12853,"Armor") -> 471.38 | P29: =AVERAGE(N29:O29) -> 414.14 | Q29: =_xlfn.LET(_xlpm.v,_xlfn.XLOOKUP(Table2[[#This Row],[Craft]],Table4[Material],Table4[Home POE],""),IF(_xlpm.v="","",_xlpm.v)) | R29: =_xlfn.LET(_xlpm.v,_xlfn.XLOOKUP(Table2[[#This Row],[Craft]],Table4[Material],Table4[Home Rarity],""),IF(_xlpm.v="","",_xlpm.v))
A30: Cloth | B30: 0.25 – 0.52 | C30: =COUNTIFS(Table2[Home POE],"Lower",Table2[Category],A30) -> 0 | G30: Wood | H30: Broon | J30: =_xlfn.MAXIFS(Import!$G$2:$G$12853,Import!$B$2:$B$12853,$H30) -> 26.8 | K30: =_xlfn.MINIFS(Import!$G$2:$G$12853,Import!$B$2:$B$12853,$H30) -> 0.04 | L30: {=IFERROR(_xlfn.TEXTAFTER(INDEX(Import!$D$2:$D$12853,MATCH(1,(Import!$B$2:$B$12853=$H30)*(Import!$G$2:$G$12853=$J30),0))," "),"")} -> Lamellar Cuirass | M30: {=IFERROR(_xlfn.TEXTAFTER(INDEX(Import!$D$2:$D$12853,MATCH(1,(Import!$B$2:$B$12853=$H30)*(Import!$G$2:$G$12853=$K30),0))," "),"")} -> Bolt | N30: =SUMIFS(Import!$G$2:$G$12853,Import!$B$2:$B$12853,$H30,Import!$C$2:$C$12853,"Weapon") -> 356.9 | O30: =SUMIFS(Import!$G$2:$G$12853,Import!$B$2:$B$12853,$H30,Import!$C$2:$C$12853,"Armor") -> 382.22 | P30: =AVERAGE(N30:O30) -> 369.56 | Q30: =_xlfn.LET(_xlpm.v,_xlfn.XLOOKUP(Table2[[#This Row],[Craft]],Table4[Material],Table4[Home POE],""),IF(_xlpm.v="","",_xlpm.v)) | R30: =_xlfn.LET(_xlpm.v,_xlfn.XLOOKUP(Table2[[#This Row],[Craft]],Table4[Material],Table4[Home Rarity],""),IF(_xlpm.v="","",_xlpm.v))
A31: Leather | B31: 0.42 – 0.97 | C31: =COUNTIFS(Table2[Home POE],"Lower",Table2[Category],A31) -> 0 | G31: Glass | H31: Byeshk | I31: 17 | J31: =_xlfn.MAXIFS(Import!$G$2:$G$12853,Import!$B$2:$B$12853,$H31) -> 40.75 | K31: =_xlfn.MINIFS(Import!$G$2:$G$12853,Import!$B$2:$B$12853,$H31) -> 0.04 | L31: {=IFERROR(_xlfn.TEXTAFTER(INDEX(Import!$D$2:$D$12853,MATCH(1,(Import!$B$2:$B$12853=$H31)*(Import!$G$2:$G$12853=$J31),0))," "),"")} -> Tower Shield | M31: {=IFERROR(_xlfn.TEXTAFTER(INDEX(Import!$D$2:$D$12853,MATCH(1,(Import!$B$2:$B$12853=$H31)*(Import!$G$2:$G$12853=$K31),0))," "),"")} -> Bolt | N31: =SUMIFS(Import!$G$2:$G$12853,Import!$B$2:$B$12853,$H31,Import!$C$2:$C$12853,"Weapon") -> 356.9 | O31: =SUMIFS(Import!$G$2:$G$12853,Import!$B$2:$B$12853,$H31,Import!$C$2:$C$12853,"Armor") -> 444.66 | P31: =AVERAGE(N31:O31) -> 400.78 | Q31: =_xlfn.LET(_xlpm.v,_xlfn.XLOOKUP(Table2[[#This Row],[Craft]],Table4[Material],Table4[Home POE],""),IF(_xlpm.v="","",_xlpm.v)) -> Material | R31: =_xlfn.LET(_xlpm.v,_xlfn.XLOOKUP(Table2[[#This Row],[Craft]],Table4[Material],Table4[Home Rarity],""),IF(_xlpm.v="","",_xlpm.v)) -> 3
A32: Wood | B32: 0.79 – 1.82 | C32: =COUNTIFS(Table2[Home POE],"Lower",Table2[Category],A32) -> 0 | G32: Stone | H32: Ceramic | I32: 13 | J32: =_xlfn.MAXIFS(Import!$G$2:$G$12853,Import!$B$2:$B$12853,$H32) -> 48 | K32: =_xlfn.MINIFS(Import!$G$2:$G$12853,Import!$B$2:$B$12853,$H32) -> 0.04 | L32: {=IFERROR(_xlfn.TEXTAFTER(INDEX(Import!$D$2:$D$12853,MATCH(1,(Import!$B$2:$B$12853=$H32)*(Import!$G$2:$G$12853=$J32),0))," "),"")} -> Lamellar Cuirass | M32: {=IFERROR(_xlfn.TEXTAFTER(INDEX(Import!$D$2:$D$12853,MATCH(1,(Import!$B$2:$B$12853=$H32)*(Import!$G$2:$G$12853=$K32),0))," "),"")} -> Bolt | N32: =SUMIFS(Import!$G$2:$G$12853,Import!$B$2:$B$12853,$H32,Import!$C$2:$C$12853,"Weapon") -> 356.9 | O32: =SUMIFS(Import!$G$2:$G$12853,Import!$B$2:$B$12853,$H32,Import!$C$2:$C$12853,"Armor") -> 617.56 | P32: =AVERAGE(N32:O32) -> 487.23 | Q32: =_xlfn.LET(_xlpm.v,_xlfn.XLOOKUP(Table2[[#This Row],[Craft]],Table4[Material],Table4[Home POE],""),IF(_xlpm.v="","",_xlpm.v)) -> Material | R32: =_xlfn.LET(_xlpm.v,_xlfn.XLOOKUP(Table2[[#This Row],[Craft]],Table4[Material],Table4[Home Rarity],""),IF(_xlpm.v="","",_xlpm.v)) -> 1
A33: Osso | B33: 1.49 – 3.42 | C33: =COUNTIFS(Table2[Home POE],"Lower",Table2[Category],A33) -> 0 | G33: Osso | H33: Chitin | I33: 6 | J33: =_xlfn.MAXIFS(Import!$G$2:$G$12853,Import!$B$2:$B$12853,$H33) -> 22.8 | K33: =_xlfn.MINIFS(Import!$G$2:$G$12853,Import!$B$2:$B$12853,$H33) -> 0.04 | L33: {=IFERROR(_xlfn.TEXTAFTER(INDEX(Import!$D$2:$D$12853,MATCH(1,(Import!$B$2:$B$12853=$H33)*(Import!$G$2:$G$12853=$J33),0))," "),"")} -> Lamellar Cuirass | M33: {=IFERROR(_xlfn.TEXTAFTER(INDEX(Import!$D$2:$D$12853,MATCH(1,(Import!$B$2:$B$12853=$H33)*(Import!$G$2:$G$12853=$K33),0))," "),"")} -> Bolt | N33: =SUMIFS(Import!$G$2:$G$12853,Import!$B$2:$B$12853,$H33,Import!$C$2:$C$12853,"Weapon") -> 356.9 | O33: =SUMIFS(Import!$G$2:$G$12853,Import!$B$2:$B$12853,$H33,Import!$C$2:$C$12853,"Armor") -> 350.4 | P33: =AVERAGE(N33:O33) -> 353.65 | Q33: =_xlfn.LET(_xlpm.v,_xlfn.XLOOKUP(Table2[[#This Row],[Craft]],Table4[Material],Table4[Home POE],""),IF(_xlpm.v="","",_xlpm.v)) -> Material | R33: =_xlfn.LET(_xlpm.v,_xlfn.XLOOKUP(Table2[[#This Row],[Craft]],Table4[Material],Table4[Home Rarity],""),IF(_xlpm.v="","",_xlpm.v)) -> 1
A34: Glass | B34: 2.79 – 6.40 | C34: =COUNTIFS(Table2[Home POE],"Lower",Table2[Category],A34) -> 1 | G34: Metal | H34: Cinnabryl | I34: 13.5 | J34: =_xlfn.MAXIFS(Import!$G$2:$G$12853,Import!$B$2:$B$12853,$H34) -> 38.27 | K34: =_xlfn.MINIFS(Import!$G$2:$G$12853,Import!$B$2:$B$12853,$H34) -> 0.04 | L34: {=IFERROR(_xlfn.TEXTAFTER(INDEX(Import!$D$2:$D$12853,MATCH(1,(Import!$B$2:$B$12853=$H34)*(Import!$G$2:$G$12853=$J34),0))," "),"")} -> Lamellar Cuirass | M34: {=IFERROR(_xlfn.TEXTAFTER(INDEX(Import!$D$2:$D$12853,MATCH(1,(Import!$B$2:$B$12853=$H34)*(Import!$G$2:$G$12853=$K34),0))," "),"")} -> Bolt | N34: =SUMIFS(Import!$G$2:$G$12853,Import!$B$2:$B$12853,$H34,Import!$C$2:$C$12853,"Weapon") -> 356.9 | O34: =SUMIFS(Import!$G$2:$G$12853,Import!$B$2:$B$12853,$H34,Import!$C$2:$C$12853,"Armor") -> 486.26 | P34: =AVERAGE(N34:O34) -> 421.58 | Q34: =_xlfn.LET(_xlpm.v,_xlfn.XLOOKUP(Table2[[#This Row],[Craft]],Table4[Material],Table4[Home POE],""),IF(_xlpm.v="","",_xlpm.v)) | R34: =_xlfn.LET(_xlpm.v,_xlfn.XLOOKUP(Table2[[#This Row],[Craft]],Table4[Material],Table4[Home Rarity],""),IF(_xlpm.v="","",_xlpm.v))
A35: Stone | B35: 5.22 – 11.98 | C35: =COUNTIFS(Table2[Home POE],"Lower",Table2[Category],A35) -> 1 | G35: Stone | H35: Coldron | J35: =_xlfn.MAXIFS(Import!$G$2:$G$12853,Import!$B$2:$B$12853,$H35) -> 48.5 | K35: =_xlfn.MINIFS(Import!$G$2:$G$12853,Import!$B$2:$B$12853,$H35) -> 0.04 | L35: {=IFERROR(_xlfn.TEXTAFTER(INDEX(Import!$D$2:$D$12853,MATCH(1,(Import!$B$2:$B$12853=$H35)*(Import!$G$2:$G$12853=$J35),0))," "),"")} -> Lamellar Cuirass | M35: {=IFERROR(_xlfn.TEXTAFTER(INDEX(Import!$D$2:$D$12853,MATCH(1,(Import!$B$2:$B$12853=$H35)*(Import!$G$2:$G$12853=$K35),0))," "),"")} -> Bolt | N35: =SUMIFS(Import!$G$2:$G$12853,Import!$B$2:$B$12853,$H35,Import!$C$2:$C$12853,"Weapon") -> 356.9 | O35: =SUMIFS(Import!$G$2:$G$12853,Import!$B$2:$B$12853,$H35,Import!$C$2:$C$12853,"Armor") -> 624.74 | P35: =AVERAGE(N35:O35) -> 490.82 | Q35: =_xlfn.LET(_xlpm.v,_xlfn.XLOOKUP(Table2[[#This Row],[Craft]],Table4[Material],Table4[Home POE],""),IF(_xlpm.v="","",_xlpm.v)) -> Material | R35: =_xlfn.LET(_xlpm.v,_xlfn.XLOOKUP(Table2[[#This Row],[Craft]],Table4[Material],Table4[Home Rarity],""),IF(_xlpm.v="","",_xlpm.v)) -> 2
A36: Metal | B36: 9.78 – 20.00 | C36: =COUNTIFS(Table2[Home POE],"Lower",Table2[Category],A36) -> 1 | G36: Metal | H36: Copper | I36: 10.5 | J36: =_xlfn.MAXIFS(Import!$G$2:$G$12853,Import!$B$2:$B$12853,$H36) -> 37.47 | K36: =_xlfn.MINIFS(Import!$G$2:$G$12853,Import!$B$2:$B$12853,$H36) -> 0.04 | L36: {=IFERROR(_xlfn.TEXTAFTER(INDEX(Import!$D$2:$D$12853,MATCH(1,(Import!$B$2:$B$12853=$H36)*(Import!$G$2:$G$12853=$J36),0))," "),"")} -> Lamellar Cuirass | M36: {=IFERROR(_xlfn.TEXTAFTER(INDEX(Import!$D$2:$D$12853,MATCH(1,(Import!$B$2:$B$12853=$H36)*(Import!$G$2:$G$12853=$K36),0))," "),"")} -> Bolt | N36: =SUMIFS(Import!$G$2:$G$12853,Import!$B$2:$B$12853,$H36,Import!$C$2:$C$12853,"Weapon") -> 356.9 | O36: =SUMIFS(Import!$G$2:$G$12853,Import!$B$2:$B$12853,$H36,Import!$C$2:$C$12853,"Armor") -> 477.3 | P36: =AVERAGE(N36:O36) -> 417.1 | Q36: =_xlfn.LET(_xlpm.v,_xlfn.XLOOKUP(Table2[[#This Row],[Craft]],Table4[Material],Table4[Home POE],""),IF(_xlpm.v="","",_xlpm.v)) | R36: =_xlfn.LET(_xlpm.v,_xlfn.XLOOKUP(Table2[[#This Row],[Craft]],Table4[Material],Table4[Home Rarity],""),IF(_xlpm.v="","",_xlpm.v))
A37: POE: Feywild Rarity Calc | G37: Stone | H37: Corundum | I37: 15 | J37: =_xlfn.MAXIFS(Import!$G$2:$G$12853,Import!$B$2:$B$12853,$H37) -> 48.4 | K37: =_xlfn.MINIFS(Import!$G$2:$G$12853,Import!$B$2:$B$12853,$H37) -> 0.04 | L37: {=IFERROR(_xlfn.TEXTAFTER(INDEX(Import!$D$2:$D$12853,MATCH(1,(Import!$B$2:$B$12853=$H37)*(Import!$G$2:$G$12853=$J37),0))," "),"")} -> Lamellar Cuirass | M37: {=IFERROR(_xlfn.TEXTAFTER(INDEX(Import!$D$2:$D$12853,MATCH(1,(Import!$B$2:$B$12853=$H37)*(Import!$G$2:$G$12853=$K37),0))," "),"")} -> Bolt | N37: =SUMIFS(Import!$G$2:$G$12853,Import!$B$2:$B$12853,$H37,Import!$C$2:$C$12853,"Weapon") -> 356.9 | O37: =SUMIFS(Import!$G$2:$G$12853,Import!$B$2:$B$12853,$H37,Import!$C$2:$C$12853,"Armor") -> 623.24 | P37: =AVERAGE(N37:O37) -> 490.07 | Q37: =_xlfn.LET(_xlpm.v,_xlfn.XLOOKUP(Table2[[#This Row],[Craft]],Table4[Material],Table4[Home POE],""),IF(_xlpm.v="","",_xlpm.v)) -> Material | R37: =_xlfn.LET(_xlpm.v,_xlfn.XLOOKUP(Table2[[#This Row],[Craft]],Table4[Material],Table4[Home Rarity],""),IF(_xlpm.v="","",_xlpm.v)) -> 4
B38: Normal POE Weight | G38: Cloth | H38: Cotton | I38: 1.2 | J38: =_xlfn.MAXIFS(Import!$G$2:$G$12853,Import!$B$2:$B$12853,$H38) -> 22.67 | K38: =_xlfn.MINIFS(Import!$G$2:$G$12853,Import!$B$2:$B$12853,$H38) -> 0.04 | L38: {=IFERROR(_xlfn.TEXTAFTER(INDEX(Import!$D$2:$D$12853,MATCH(1,(Import!$B$2:$B$12853=$H38)*(Import!$G$2:$G$12853=$J38),0))," "),"")} -> Hunting Trap (Large) | M38: {=IFERROR(_xlfn.TEXTAFTER(INDEX(Import!$D$2:$D$12853,MATCH(1,(Import!$B$2:$B$12853=$H38)*(Import!$G$2:$G$12853=$K38),0))," "),"")} -> Bolt | N38: =SUMIFS(Import!$G$2:$G$12853,Import!$B$2:$B$12853,$H38,Import!$C$2:$C$12853,"Weapon") -> 356.9 | O38: =SUMIFS(Import!$G$2:$G$12853,Import!$B$2:$B$12853,$H38,Import!$C$2:$C$12853,"Armor") -> 312.8 | P38: =AVERAGE(N38:O38) -> 334.85 | Q38: =_xlfn.LET(_xlpm.v,_xlfn.XLOOKUP(Table2[[#This Row],[Craft]],Table4[Material],Table4[Home POE],""),IF(_xlpm.v="","",_xlpm.v)) -> Material | R38: =_xlfn.LET(_xlpm.v,_xlfn.XLOOKUP(Table2[[#This Row],[Craft]],Table4[Material],Table4[Home Rarity],""),IF(_xlpm.v="","",_xlpm.v)) -> 2
A39: Cloth | B39: 0.25 – 0.52 | C39: =COUNTIFS(Table2[Home POE],"Feywild",Table2[Category],A39) -> 0 | G39: Stone | H39: Crystal | I39: 16 | J39: =_xlfn.MAXIFS(Import!$G$2:$G$12853,Import!$B$2:$B$12853,$H39) -> 48.69 | K39: =_xlfn.MINIFS(Import!$G$2:$G$12853,Import!$B$2:$B$12853,$H39) -> 0.04 | L39: {=IFERROR(_xlfn.TEXTAFTER(INDEX(Import!$D$2:$D$12853,MATCH(1,(Import!$B$2:$B$12853=$H39)*(Import!$G$2:$G$12853=$J39),0))," "),"")} -> Lamellar Cuirass | M39: {=IFERROR(_xlfn.TEXTAFTER(INDEX(Import!$D$2:$D$12853,MATCH(1,(Import!$B$2:$B$12853=$H39)*(Import!$G$2:$G$12853=$K39),0))," "),"")} -> Bolt | N39: =SUMIFS(Import!$G$2:$G$12853,Import!$B$2:$B$12853,$H39,Import!$C$2:$C$12853,"Weapon") -> 356.9 | O39: =SUMIFS(Import!$G$2:$G$12853,Import!$B$2:$B$12853,$H39,Import!$C$2:$C$12853,"Armor") -> 627.46 | P39: =AVERAGE(N39:O39) -> 492.18 | Q39: =_xlfn.LET(_xlpm.v,_xlfn.XLOOKUP(Table2[[#This Row],[Craft]],Table4[Material],Table4[Home POE],""),IF(_xlpm.v="","",_xlpm.v)) -> Material | R39: =_xlfn.LET(_xlpm.v,_xlfn.XLOOKUP(Table2[[#This Row],[Craft]],Table4[Material],Table4[Home Rarity],""),IF(_xlpm.v="","",_xlpm.v)) -> 3
A40: Leather | B40: 0.42 – 0.97 | C40: =COUNTIFS(Table2[Home POE],"Feywild",Table2[Category],A40) -> 0 | G40: Leather | H40: Cuero | I40: 4.3 | J40: =_xlfn.MAXIFS(Import!$G$2:$G$12853,Import!$B$2:$B$12853,$H40) -> 22.67 | K40: =_xlfn.MINIFS(Import!$G$2:$G$12853,Import!$B$2:$B$12853,$H40) -> 0.04 | L40: {=IFERROR(_xlfn.TEXTAFTER(INDEX(Import!$D$2:$D$12853,MATCH(1,(Import!$B$2:$B$12853=$H40)*(Import!$G$2:$G$12853=$J40),0))," "),"")} -> Hunting Trap (Large) | M40: {=IFERROR(_xlfn.TEXTAFTER(INDEX(Import!$D$2:$D$12853,MATCH(1,(Import!$B$2:$B$12853=$H40)*(Import!$G$2:$G$12853=$K40),0))," "),"")} -> Bolt | N40: =SUMIFS(Import!$G$2:$G$12853,Import!$B$2:$B$12853,$H40,Import!$C$2:$C$12853,"Weapon") -> 356.9 | O40: =SUMIFS(Import!$G$2:$G$12853,Import!$B$2:$B$12853,$H40,Import!$C$2:$C$12853,"Armor") -> 328.3 | P40: =AVERAGE(N40:O40) -> 342.6 | Q40: =_xlfn.LET(_xlpm.v,_xlfn.XLOOKUP(Table2[[#This Row],[Craft]],Table4[Material],Table4[Home POE],""),IF(_xlpm.v="","",_xlpm.v)) -> Material | R40: =_xlfn.LET(_xlpm.v,_xlfn.XLOOKUP(Table2[[#This Row],[Craft]],Table4[Material],Table4[Home Rarity],""),IF(_xlpm.v="","",_xlpm.v)) -> 1
...

Sheet Import
A1: Category | B1: Craft | C1: Equipment | D1: New Item Name | E1: New Image Path | F1: Magical | G1: Item Weight | H1: Weight Formula
A2: =_xlfn.XLOOKUP(B2,Ingot!$H$12:$H$119,Ingot!$G$12:$G$119,"") -> Metal | B2: Adamantine | C2: Armor | D2: Adamantine Gamberson Cuirass | E2: modules/a-knights-dream/Item/equip_armor_gamberson_cuirass_adamantine.webp | F2: Yes | G2: 30.5
A3: =_xlfn.XLOOKUP(B3,Ingot!$H$12:$H$119,Ingot!$G$12:$G$119,"") -> Metal | B3: Adamantine | C3: Armor | D3: Adamantine Gamberson Gauntlets | E3: modules/a-knights-dream/Item/equip_armor_gamberson_gauntlets_adamantine.webp | F3: Yes | G3: 6.1
A4: =_xlfn.XLOOKUP(B4,Ingot!$H$12:$H$119,Ingot!$G$12:$G$119,"") -> Metal | B4: Adamantine | C4: Armor | D4: Adamantine Gamberson Greaves | E4: modules/a-knights-dream/Item/equip_armor_gamberson_greaves_adamantine.webp | F4: Yes | G4: 6.1
A5: =_xlfn.XLOOKUP(B5,Ingot!$H$12:$H$119,Ingot!$G$12:$G$119,"") -> Metal | B5: Adamantine | C5: Armor | D5: Adamantine Jack Gauntlets | E5: modules/a-knights-dream/Item/equip_armor_jack_gauntlets_adamantine.webp | F5: Yes | G5: 7
A6: =_xlfn.XLOOKUP(B6,Ingot!$H$12:$H$119,Ingot!$G$12:$G$119,"") -> Metal | B6: Adamantine | C6: Armor | D6: Adamantine Jack Greaves | E6: modules/a-knights-dream/Item/equip_armor_jack_greaves_adamantine.webp | F6: Yes | G6: 7
A7: =_xlfn.XLOOKUP(B7,Ingot!$H$12:$H$119,Ingot!$G$12:$G$119,"") -> Metal | B7: Adamantine | C7: Armor | D7: Adamantine Tunic Gauntlets | E7: modules/a-knights-dream/Item/equip_armor_tunic_gauntlets_adamantine.webp | F7: Yes | G7: 5.8
A8: =_xlfn.XLOOKUP(B8,Ingot!$H$12:$H$119,Ingot!$G$12:$G$119,"") -> Metal | B8: Adamantine | C8: Armor | D8: Adamantine Tunic Greaves | E8: modules/a-knights-dream/Item/equip_armor_tunic_greaves_adamantine.webp | F8: Yes | G8: 5.8
A9: =_xlfn.XLOOKUP(B9,Ingot!$H$12:$H$119,Ingot!$G$12:$G$119,"") -> Metal | B9: Adamantine | C9: Armor | D9: Adamantine Gamberson Helmet | E9: modules/a-knights-dream/Item/equip_armor_gamberson_helmet_adamantine.webp | F9: Yes | G9: 5
A10: =_xlfn.XLOOKUP(B10,Ingot!$H$12:$H$119,Ingot!$G$12:$G$119,"") -> Metal | B10: Adamantine | C10: Armor | D10: Adamantine Gamberson Pauldron | E10: modules/a-knights-dream/Item/equip_armor_gamberson_pauldron_adamantine.webp | F10: Yes | G10: 10
A11: =_xlfn.XLOOKUP(B11,Ingot!$H$12:$H$119,Ingot!$G$12:$G$119,"") -> Metal | B11: Adamantine | C11: Armor | D11: Adamantine Jack Helmet | E11: modules/a-knights-dream/Item/equip_armor_jack_helmet_adamantine.webp | F11: Yes | G11: 5
A12: =_xlfn.XLOOKUP(B12,Ingot!$H$12:$H$119,Ingot!$G$12:$G$119,"") -> Metal | B12: Adamantine | C12: Armor | D12: Adamantine Tunic Helmet | E12: modules/a-knights-dream/Item/equip_armor_tunic_helmet_adamantine.webp | F12: Yes | G12: 5
A13: =_xlfn.XLOOKUP(B13,Ingot!$H$12:$H$119,Ingot!$G$12:$G$119,"") -> Metal | B13: Adamantine | C13: Armor | D13: Adamantine Lamellar Cuirass | E13: modules/a-knights-dream/Item/equip_armor_lamellar_cuirass_adamantine.webp | G13: 40
A14: =_xlfn.XLOOKUP(B14,Ingot!$H$12:$H$119,Ingot!$G$12:$G$119,"") -> Metal | B14: Adamantine | C14: Armor | D14: Adamantine Platemail Cuirass | E14: modules/a-knights-dream/Item/equip_armor_platemail_cuirass_adamantine.webp | G14: 39.5
A15: =_xlfn.XLOOKUP(B15,Ingot!$H$12:$H$119,Ingot!$G$12:$G$119,"") -> Metal | B15: Adamantine | C15: Armor | D15: Adamantine Brigantine Cuirass | E15: modules/a-knights-dream/Item/equip_armor_brigantine_cuirass_adamantine.webp | G15: 37
A16: =_xlfn.XLOOKUP(B16,Ingot!$H$12:$H$119,Ingot!$G$12:$G$119,"") -> Metal | B16: Adamantine | C16: Armor | D16: Adamantine Jack Cuirass | E16: modules/a-knights-dream/Item/equip_armor_jack_cuirass_adamantine.webp | G16: 35
A17: =_xlfn.XLOOKUP(B17,Ingot!$H$12:$H$119,Ingot!$G$12:$G$119,"") -> Metal | B17: Adamantine | C17: Shield | D17: Adamantine Tower Shield | E17: modules/a-knights-dream/Item/equip_armor_shield_tower_adamantine.webp | G17: =(VLOOKUP(B17,Ingot!H:I,2,FALSE()) * 3) - 10.25 -> 49.75
A18: =_xlfn.XLOOKUP(B18,Ingot!$H$12:$H$119,Ingot!$G$12:$G$119,"") -> Metal | B18: Adamantine | C18: Armor | D18: Adamantine Hauberk Cuirass | E18: modules/a-knights-dream/Item/equip_armor_hauberk_cuirass_adamantine.webp | G18: 33
A19: =_xlfn.XLOOKUP(B19,Ingot!$H$12:$H$119,Ingot!$G$12:$G$119,"") -> Metal | B19: Adamantine | C19: Shield | D19: Adamantine Kite Shield | E19: modules/a-knights-dream/Item/equip_armor_shield_kite_adamantine.webp | G19: =((VLOOKUP(B19,Ingot!H:I,2,FALSE()) * 3) - 10.25) * 0.75 -> 37.3125
A20: =_xlfn.XLOOKUP(B20,Ingot!$H$12:$H$119,Ingot!$G$12:$G$119,"") -> Metal | B20: Adamantine | C20: Armor | D20: Adamantine Lamellar Pauldron | E20: modules/a-knights-dream/Item/equip_armor_lamellar_pauldron_adamantine.webp | G20: 10.4
A21: =_xlfn.XLOOKUP(B21,Ingot!$H$12:$H$119,Ingot!$G$12:$G$119,"") -> Metal | B21: Adamantine | C21: Armor | D21: Adamantine Chainmail Cuirass | E21: modules/a-knights-dream/Item/equip_armor_chainmail_cuirass_adamantine.webp | G21: 31.5
A22: =_xlfn.XLOOKUP(B22,Ingot!$H$12:$H$119,Ingot!$G$12:$G$119,"") -> Metal | B22: Adamantine | C22: Armor | D22: Adamantine Platemail Pauldron | E22: modules/a-knights-dream/Item/equip_armor_platemail_pauldron_adamantine.webp | G22: 10.27
A23: =_xlfn.XLOOKUP(B23,Ingot!$H$12:$H$119,Ingot!$G$12:$G$119,"") -> Metal | B23: Adamantine | C23: Shield | D23: Adamantine Oval Shield | E23: modules/a-knights-dream/Item/equip_armor_shield_oval_adamantine.webp | G23: =((VLOOKUP(B23,Ingot!H:I,2,FALSE()) * 3) - 10.25) * 0.5625 -> 27.984375
A24: =_xlfn.XLOOKUP(B24,Ingot!$H$12:$H$119,Ingot!$G$12:$G$119,"") -> Metal | B24: Adamantine | C24: Armor | D24: Adamantine Brigantine Pauldron | E24: modules/a-knights-dream/Item/equip_armor_brigantine_pauldron_adamantine.webp | G24: 10
A25: =_xlfn.XLOOKUP(B25,Ingot!$H$12:$H$119,Ingot!$G$12:$G$119,"") -> Metal | B25: Adamantine | C25: Armor | D25: Adamantine Jack Pauldron | E25: modules/a-knights-dream/Item/equip_armor_jack_pauldron_adamantine.webp | G25: 10
A26: =_xlfn.XLOOKUP(B26,Ingot!$H$12:$H$119,Ingot!$G$12:$G$119,"") -> Metal | B26: Adamantine | C26: Weapon | D26: Adamantine Hunting Trap (Large) | E26: modules/a-knights-dream/Item/equip_weapon_trap_hunting_large_adamantine.webp | G26: 22.67
A27: =_xlfn.XLOOKUP(B27,Ingot!$H$12:$H$119,Ingot!$G$12:$G$119,"") -> Metal | B27: Adamantine | C27: Shield | D27: Adamantine Heater Shield | E27: modules/a-knights-dream/Item/equip_armor_shield_heater_adamantine.webp | G27: =((VLOOKUP(B27,Ingot!H:I,2,FALSE()) * 3) - 10.25) * 0.421875 -> 20.988281
A28: =_xlfn.XLOOKUP(B28,Ingot!$H$12:$H$119,Ingot!$G$12:$G$119,"") -> Metal | B28: Adamantine | C28: Armor | D28: Adamantine Hauberk Pauldron | E28: modules/a-knights-dream/Item/equip_armor_hauberk_pauldron_adamantine.webp | G28: 10
A29: =_xlfn.XLOOKUP(B29,Ingot!$H$12:$H$119,Ingot!$G$12:$G$119,"") -> Metal | B29: Adamantine | C29: Armor | D29: Adamantine Tunic Cuirass | E29: modules/a-knights-dream/Item/equip_armor_tunic_cuirass_adamantine.webp | F29: Yes | G29: 29
A30: =_xlfn.XLOOKUP(B30,Ingot!$H$12:$H$119,Ingot!$G$12:$G$119,"") -> Metal | B30: Adamantine | C30: Armor | D30: Adamantine Chainmail Pauldron | E30: modules/a-knights-dream/Item/equip_armor_chainmail_pauldron_adamantine.webp | G30: 10
A31: =_xlfn.XLOOKUP(B31,Ingot!$H$12:$H$119,Ingot!$G$12:$G$119,"") -> Metal | B31: Adamantine | C31: Shield | D31: Adamantine Round Shield | E31: modules/a-knights-dream/Item/equip_armor_shield_round_adamantine.webp | G31: =VLOOKUP(B31,Ingot!H:I,2,FALSE()) * 0.75 -> 15
A32: =_xlfn.XLOOKUP(B32,Ingot!$H$12:$H$119,Ingot!$G$12:$G$119,"") -> Metal | B32: Adamantine | C32: Weapon | D32: Adamantine Lance | E32: modules/a-knights-dream/Item/equip_weapon_lance_adamantine.webp | G32: 13.07
A33: =_xlfn.XLOOKUP(B33,Ingot!$H$12:$H$119,Ingot!$G$12:$G$119,"") -> Metal | B33: Adamantine | C33: Weapon | D33: Adamantine Hunting Trap | E33: modules/a-knights-dream/Item/equip_weapon_trap_hunting_adamantine.webp | G33: 12.64
A34: =_xlfn.XLOOKUP(B34,Ingot!$H$12:$H$119,Ingot!$G$12:$G$119,"") -> Metal | B34: Adamantine | C34: Weapon | D34: Adamantine Great Labrys | E34: modules/a-knights-dream/Item/equip_weapon_axe_labrys_great_adamantine.webp | G34: 11.81
A35: =_xlfn.XLOOKUP(B35,Ingot!$H$12:$H$119,Ingot!$G$12:$G$119,"") -> Metal | B35: Adamantine | C35: Armor | D35: Adamantine Brigantine Gauntlets | E35: modules/a-knights-dream/Item/equip_armor_brigantine_gauntlets_adamantine.webp | G35: 7.4
A36: =_xlfn.XLOOKUP(B36,Ingot!$H$12:$H$119,Ingot!$G$12:$G$119,"") -> Metal | B36: Adamantine | C36: Armor | D36: Adamantine Brigantine Greaves | E36: modules/a-knights-dream/Item/equip_armor_brigantine_greaves_adamantine.webp | G36: 7.4
A37: =_xlfn.XLOOKUP(B37,Ingot!$H$12:$H$119,Ingot!$G$12:$G$119,"") -> Metal | B37: Adamantine | C37: Armor | D37: Adamantine Lamellar Gauntlets | E37: modules/a-knights-dream/Item/equip_armor_lamellar_gauntlets_adamantine.webp | G37: 8
A38: =_xlfn.XLOOKUP(B38,Ingot!$H$12:$H$119,Ingot!$G$12:$G$119,"") -> Metal | B38: Adamantine | C38: Armor | D38: Adamantine Lamellar Greaves | E38: modules/a-knights-dream/Item/equip_armor_lamellar_greaves_adamantine.webp | G38: 8
A39: =_xlfn.XLOOKUP(B39,Ingot!$H$12:$H$119,Ingot!$G$12:$G$119,"") -> Metal | B39: Adamantine | C39: Armor | D39: Adamantine Platemail Gauntlets | E39: modules/a-knights-dream/Item/equip_armor_platemail_gauntlets_adamantine.webp | G39: 7.9
A40: =_xlfn.XLOOKUP(B40,Ingot!$H$12:$H$119,Ingot!$G$12:$G$119,"") -> Metal | B40: Adamantine | C40: Armor | D40: Adamantine Platemail Greaves | E40: modules/a-knights-dream/Item/equip_armor_platemail_greaves_adamantine.webp | G40: 7.9
...

Sheet Effects
A1: Source Book | B1: Category | C1: Material | D1: Home POE | E1: Home Rarity | F1: Effect | G1: Common Trade POE's | H1: Column1 | I1: Rarity Tier Reference
B2: =IFERROR(_xlfn.XLOOKUP(C2,Table2[Craft],Table2[Category]),"") -> Leather | C2: Abyski | I2: # | J2: Tier | K2: Level Rec | L2: Description | M2: Value
B3: =IFERROR(_xlfn.XLOOKUP(C3,Table2[Craft],Table2[Category]),"") | C3: Adamant | I3: 0 | J3: Mundane | K3: — | L3: Non-magical, ordinary equipment. | M3: Standard cost
A4: DMG | B4: =IFERROR(_xlfn.XLOOKUP(C4,Table2[Craft],Table2[Category]),"") -> Metal | C4: Adamantine | D4: Material | E4: 4 | F4: grants crit damage reduction. DMG | G4: Feywild, Shadowfell | I4: 1 | J4: Common | K4: 1st+ | L4: Basic magic items, trinkets, potions of healing, and minor utility gear. | M4: 100 – 500 gp
A5: KD | B5: =IFERROR(_xlfn.XLOOKUP(C5,Table2[Craft],Table2[Category]),"") -> Glass | C5: Amber | D5: Material | E5: 3 | G5: Material | I5: 2 | J5: Uncommon | K5: 1st+ | L5: Items that provide noticeable benefits, such as a +1 weapon, Bag of Holding, or specific resistance-granting armors. | M5: 101 – 500 gp
B6: =IFERROR(_xlfn.XLOOKUP(C6,Table2[Craft],Table2[Category]),"") | C6: Arambarium | I6: 3 | J6: Rare | K6: 5th+ | L6: Significant upgrades, such as a +2 weapon, Fly potions, or stat-boosting items like Belt of Giant Strength. | M6: 501 – 5,000 gp
A7: MoF | B7: =IFERROR(_xlfn.XLOOKUP(C7,Table2[Craft],Table2[Category]),"") -> Metal | C7: Arandur | D7: Feywild | F7: grants sonic resistance. MoF | I7: 4 | J7: Very Rare | K7: 11th+ | L7: Highly powerful equipment that can alter the tide of combat, such as +3 weapons or high-level spell scrolls. | M7: 5,001 – 50,000 gp
B8: =IFERROR(_xlfn.XLOOKUP(C8,Table2[Craft],Table2[Category]),"") | C8: Arjale | I8: 5 | J8: Legendary | K8: 17th+ | L8: World-shaking items, powerful artifacts, and unique equipment reserved for top-tier adventurers. | M8: 50,001+ gp
A9: KD | B9: =IFERROR(_xlfn.XLOOKUP(C9,Table2[Craft],Table2[Category]),"") -> Wood | C9: Ash | D9: Material | E9: 1 | G9: All | I9: 6 | J9: Artifact | K9: 20th | L9: Unique, one-of-a-kind relics of immense power (often with their own personalities or corrupting effects) that drive major campaign narratives. | M9: Priceless
A10: BoED | B10: =IFERROR(_xlfn.XLOOKUP(C10,Table2[Craft],Table2[Category]),"") -> Metal | C10: Aurorum | D10: Upper | E10: 5 | F10: restores itself if sundered. BoED
A11: A&EG | B11: =IFERROR(_xlfn.XLOOKUP(C11,Table2[Craft],Table2[Category]),"") -> Metal | C11: Baatorium | D11: Lower | E11: 3 | F11: enhancement bonus to damage. A&EG | G11: Nine Hells | I11: Source Book Abbreviations
A12: KD | B12: =IFERROR(_xlfn.XLOOKUP(C12,Table2[Craft],Table2[Category]),"") | C12: Barium | D12: Material | E12: 5 | G12: — | I12: Abbrev. | J12: Source
A13: KD | B13: =IFERROR(_xlfn.XLOOKUP(C13,Table2[Craft],Table2[Category]),"") -> Glass | C13: Beskar | D13: Material (other setting) | E13: 4 | G13: Mandalore (Star Wars) | I13: DMG | J13: Dungeon Master's Guide (3.5e core)
A14: KD | B14: =IFERROR(_xlfn.XLOOKUP(C14,Table2[Craft],Table2[Category]),"") -> Wood | C14: Birch | D14: Material | E14: 1 | G14: All | I14: PH | J14: Planar Handbook
A15: KD | B15: =IFERROR(_xlfn.XLOOKUP(C15,Table2[Craft],Table2[Category]),"") -> Wood | C15: Bloodbark | I15: MoF | J15: Magic of Faerûn
A16: KD | B16: =IFERROR(_xlfn.XLOOKUP(C16,Table2[Craft],Table2[Category]),"") -> Wood | C16: Bludbud | I16: RoF | J16: Races of Faerûn
A17: KD | B17: =IFERROR(_xlfn.XLOOKUP(C17,Table2[Craft],Table2[Category]),"") -> Stone | C17: Blueice | D17: Lower | E17: 3 | G17: Frostfell, Cania, Stygia, Layer of Agathys | I17: FB | J17: Frostburn
A18: KD | B18: =IFERROR(_xlfn.XLOOKUP(C18,Table2[Craft],Table2[Category]),"") -> Wood | C18: Bluleaf | I18: A&EG | J18: Arms and Equipment Guide
A19: KD | B19: =IFERROR(_xlfn.XLOOKUP(C19,Table2[Craft],Table2[Category]),"") -> Leather | C19: Boiplate | I19: BoED | J19: Book of Exalted Deeds
A20: Dragon Magazine 319 | B20: =IFERROR(_xlfn.XLOOKUP(C20,Table2[Craft],Table2[Category]),"") -> Osso | C20: Bone | D20: Material | E20: 1 | F20: -2 attack and damage (min 1), hardness 6, 10 hp/inch, weighs half as much. Dragon 319 | G20: All | I20: ECS | J20: Eberron Campaign Setting
A21: KD | B21: =IFERROR(_xlfn.XLOOKUP(C21,Table2[Craft],Table2[Category]),"") -> Osso | C21: Bonemold | D21: Material | E21: 2 | G21: Morrowind (Elder Scrolls) | I21: PGtE | J21: Player's Guide to Eberron
A22: KD | B22: =IFERROR(_xlfn.XLOOKUP(C22,Table2[Craft],Table2[Category]),"") | C22: Brass | D22: Material | E22: 2 | G22: Material | I22: MoE | J22: Magic of Eberron
A23: A&EG | B23: =IFERROR(_xlfn.XLOOKUP(C23,Table2[Craft],Table2[Category]),"") -> Wood | C23: Bronwood | F23: Bronzewood reduces weight, doesn't affect hide in woodlands. A&EG | I23: SoS | J23: Secrets of Sarlona
A24: Dragon Magazine 319 p 40 | B24: =IFERROR(_xlfn.XLOOKUP(C24,Table2[Craft],Table2[Category]),"") -> Metal | C24: Bronze | F24: 1 less AC bonus compared to normal steel armors. Dragon Magazine 319 p 40 | I24: CoV | J24: Champions of Valor
A25: KD | B25: =IFERROR(_xlfn.XLOOKUP(C25,Table2[Craft],Table2[Category]),"") -> Wood | C25: Broon | I25: CW | J25: Complete Warrior
A26: ECS | B26: =IFERROR(_xlfn.XLOOKUP(C26,Table2[Craft],Table2[Category]),"") -> Glass | C26: Byeshk | D26: Material | E26: 3 | F26: deals bonus damage with bludgeoning weapons, bypasses the DR of daelkyr. ECS | G26: Material (Khorvaire) | I26: CAr | J26: Complete Arcane
B27: =IFERROR(_xlfn.XLOOKUP(C27,Table2[Craft],Table2[Category]),"") | C27: Celestial | D27: Upper | E27: 3 | G27: Material (rare) | I27: CM | J27: Complete Mage
A28: KD | B28: =IFERROR(_xlfn.XLOOKUP(C28,Table2[Craft],Table2[Category]),"") -> Stone | C28: Ceramic | D28: Material | E28: 1 | G28: All | I28: RotD | J28: Races of the Dragon
A29: RotD | B29: =IFERROR(_xlfn.XLOOKUP(C29,Table2[Craft],Table2[Category]),"") -> Osso | C29: Chitin | D29: Material | E29: 1 | F29: replaces metal, increases MDB. RotD | G29: All | I29: RotW | J29: Races of the Wild
A30: KD | B30: =IFERROR(_xlfn.XLOOKUP(C30,Table2[Craft],Table2[Category]),"") | C30: Chromium | D30: Material | E30: 5 | G30: — | I30: FF | J30: Fiend Folio
A31: Dragon Magazine 315 | B31: =IFERROR(_xlfn.XLOOKUP(C31,Table2[Craft],Table2[Category]),"") -> Metal | C31: Cinnabryl | F31: 20 hp/inch, hardness 8, used to make special talismans. Dragon 315 | I31: EXH | J31: Expanded Psionics Handbook
A32: KD | B32: =IFERROR(_xlfn.XLOOKUP(C32,Table2[Craft],Table2[Category]),"") | C32: Cobalt | D32: Material | E32: 4 | G32: Material | I32: SW | J32: Stormwrack
A33: KD | B33: =IFERROR(_xlfn.XLOOKUP(C33,Table2[Craft],Table2[Category]),"") -> Stone | C33: Coldron | D33: Material | E33: 2 | G33: All | I33: Draco | J33: Draconomicon
A34: MoF | B34: =IFERROR(_xlfn.XLOOKUP(C34,Table2[Craft],Table2[Category]),"") -> Metal | C34: Copper | F34: grants cold resistance. MoF | I34: FR | J34: Forgotten Realms Campaign Setting
A35: KD | B35: =IFERROR(_xlfn.XLOOKUP(C35,Table2[Craft],Table2[Category]),"") -> Stone | C35: Corundum | D35: Material | E35: 4 | G35: Material | I35: Dragon | J35: Dragon Magazine (issue cited inline)
A36: KD | B36: =IFERROR(_xlfn.XLOOKUP(C36,Table2[Craft],Table2[Category]),"") -> Cloth | C36: Cotton | D36: Material | E36: 2 | G36: All | I36: KD | J36: A Knight's Dream
A37: EXH | B37: =IFERROR(_xlfn.XLOOKUP(C37,Table2[Craft],Table2[Category]),"") -> Stone | C37: Crystal | D37: Material | E37: 3 | F37: replaces metal (Deep Crystal: deals bonus damage by channeling power points). EXH | G37: Underdark, Material | I37: Game-Term Abbreviations
A38: KD | B38: =IFERROR(_xlfn.XLOOKUP(C38,Table2[Craft],Table2[Category]),"") -> Leather | C38: Cuero | D38: Material | E38: 1 | G38: All | I38: Abbrev. | J38: Meaning
A39: PGtE | B39: =IFERROR(_xlfn.XLOOKUP(C39,Table2[Craft],Table2[Category]),"") -> Metal | C39: Cyrite | F39: grants a +1 resistance bonus to saves. PGtE | I39: AC | J39: Armor Class
B40: =IFERROR(_xlfn.XLOOKUP(C40,Table2[Craft],Table2[Category]),"") | C40: Dajavva | I40: ACP | J40: Armor Check Penalty
...

Sheet Material Registry
A1: Material Name | B1: Category | C1: Weight Factor | D1: Override Factor | E1: Own Property Key | F1: Key Source | G1: Also Triggers Native Property | H1: In External Override File? | I1: Proposed 3-Letter Key | J1: 3-Letter Key Notes
A2: Cotton | B2: Cloth | C2: 0.55 | E2: cotton | F2: minted by module's ready hook | H2: Unknown | I2: cot
A3: Hemp | B3: Cloth | C3: 0.55 | E3: hemp | F3: minted by module's ready hook | H3: Unknown | I3: hem
A4: Jute | B4: Cloth | C4: 0.55 | E4: jute | F4: minted by module's ready hook | H4: Unknown | I4: jut
A5: Linen | B5: Cloth | C5: 0.55 | E5: linen | F5: minted by module's ready hook | H5: Unknown | I5: lin
A6: Shadowsilk | B6: Cloth | C6: 0.55 | E6: shadowsilk | F6: minted by module's ready hook | H6: Unknown | I6: sha
A7: Silk | B7: Cloth | C7: 0.55 | E7: silk | F7: minted by module's ready hook | H7: Unknown | I7: slk | J7: collision - resolved via compound/consonant fallback
A8: Thistledown | B8: Cloth | C8: 0.55 | E8: thistledown | F8: minted by module's ready hook | H8: Unknown | I8: ths | J8: collision - resolved via compound/consonant fallback
A9: Twisted Silk | B9: Cloth | C9: 0.55 | E9: twistedsilk | F9: minted by module's ready hook | H9: Unknown | I9: twi
A10: Wool | B10: Cloth | C10: 0.55 | E10: wool | F10: minted by module's ready hook | H10: Unknown | I10: woo
A11: Amber | B11: Glass | C11: 0.9 | E11: amber | F11: minted by module's ready hook | H11: Unknown | I11: amb
A12: Beskar | B12: Glass | C12: 0.9 | E12: beskar | F12: minted by module's ready hook | H12: Unknown | I12: bes
A13: Blended Quartz | B13: Glass | C13: 0.9 | E13: blendedquartz | F13: minted by module's ready hook | H13: Unknown | I13: ble
A14: Byeshk | B14: Glass | C14: 0.9 | E14: byeshk | F14: minted by module's ready hook | H14: Unknown | I14: bye
A15: Dimeriti | B15: Glass | C15: 0.9 | E15: dimeriti | F15: minted by module's ready hook | H15: Unknown | I15: dim
A16: Ebony | B16: Glass | C16: 0.9 | E16: ebony | F16: minted by module's ready hook | H16: Unknown | I16: ebo
A17: Fluid Stone | B17: Glass | C17: 0.9 | E17: fluidstone | F17: minted by module's ready hook | H17: Unknown | I17: flu
A18: Glass | B18: Glass | C18: 0.9 | E18: glass | F18: minted by module's ready hook | H18: Unknown | I18: gla
A19: Glassteel | B19: Glass | C19: 0.9 | E19: glassteel | F19: minted by module's ready hook | H19: Unknown | I19: gls | J19: collision - resolved via compound/consonant fallback
A20: Plutite | B20: Glass | C20: 0.9 | E20: plutite | F20: minted by module's ready hook | H20: Unknown | I20: plu
A21: Pursuit | B21: Glass | C21: 0.9 | E21: pursuit | F21: minted by module's ready hook | H21: Unknown | I21: pur
A22: Shimmer Ring | B22: Glass | C22: 0.9 | E22: shimmerring | F22: minted by module's ready hook | H22: Unknown | I22: shi
A23: Shimmering | B23: Glass | C23: 0.9 | E23: shimmering | F23: minted by module's ready hook | H23: Unknown | I23: shm | J23: collision - resolved via compound/consonant fallback
A24: Stygian | B24: Glass | C24: 0.9 | E24: stygian | F24: minted by module's ready hook | H24: Unknown | I24: sty
A25: Abyssus Skin | B25: Leather | C25: 0.88 | E25: abyssusskin | F25: minted by module's ready hook | H25: Unknown | I25: aby
A26: Boiled Plate-Hide | B26: Leather | C26: 0.88 | E26: boiledplatehide | F26: minted by module's ready hook | H26: Unknown | I26: boi
A27: Cured Hide | B27: Leather | C27: 0.88 | E27: curedhide | F27: minted by module's ready hook | H27: Unknown | I27: cur
A28: Dar'ether | B28: Leather | C28: 0.88 | E28: darether | F28: minted by module's ready hook | H28: Unknown | I28: dar
A29: Deather | B29: Leather | C29: 0.88 | E29: deather | F29: minted by module's ready hook | H29: Unknown | I29: dea
A30: Feyken | B30: Leather | C30: 0.88 | E30: feyken | F30: minted by module's ready hook | H30: Unknown | I30: fey
A31: Fur Heavy | B31: Leather | C31: 0.88 | E31: furheavy | F31: minted by module's ready hook | H31: Unknown | I31: fur
A32: Fur Hide | B32: Leather | C32: 0.88 | E32: furhide | F32: minted by module's ready hook | H32: Unknown | I32: frh | J32: collision - resolved via compound/consonant fallback
A33: Heavy Fur | B33: Leather | C33: 0.88 | E33: heavyfur | F33: minted by module's ready hook | H33: Unknown | I33: hea
A34: Olyther | B34: Leather | C34: 0.88 | E34: olyther | F34: minted by module's ready hook | H34: Unknown | I34: oly
A35: Pelt Hard | B35: Leather | C35: 0.88 | E35: pelthard | F35: minted by module's ready hook | H35: Unknown | I35: pel
A36: Pelt Rigid | B36: Leather | C36: 0.88 | E36: peltrigid | F36: minted by module's ready hook | H36: Unknown | I36: plr | J36: collision - resolved via compound/consonant fallback
A37: Pelt Soft | B37: Leather | C37: 0.88 | E37: peltsoft | F37: minted by module's ready hook | H37: Unknown | I37: pls | J37: collision - resolved via compound/consonant fallback
A38: Pigskin | B38: Leather | C38: 0.88 | E38: pigskin | F38: minted by module's ready hook | H38: Unknown | I38: pig
A39: Short Fur | B39: Leather | C39: 0.88 | E39: shortfur | F39: minted by module's ready hook | H39: Unknown | I39: sho
A40: Tanned Pelt | B40: Leather | C40: 0.88 | E40: tannedpelt | F40: minted by module's ready hook | H40: Unknown | I40: tan
...

Sheet Effect Tracker
A1: Effect Name | B1: Scope | C1: Trigger | D1: dnd5e Mechanism | E1: Status | F1: Code Location | G1: Plain-Language Summary | H1: Verified Mechanical Detail | I1: Real-World Use Case | J1: Balance Notes | K1: Open Questions | L1: Last Updated
